<?xml version="1.0" ?>
<robot name="Rocker_Boggie">
<link name="base_link">
  <inertial>
    <origin rpy="0 0 0" xyz="0 0 0"/>
    <mass value="0.374127"/>
    <inertia ixx="0.001503" ixy="-0.000193" ixz="-0.000247" iyy="0.001361" iyz="-0.000189" izz="0.001919"/>
  </inertial>
  <visual>
    <origin rpy="0 0 0" xyz="0 0 0"/>
    <geometry>
      <mesh filename="package://fusion2urdf/bin_stl/base_link_m-binary.stl"/>
    </geometry>
    <material name="silver">
      <color rgba="1 0 0 1"/>
    </material>
  </visual>
  <collision>
    <origin rpy="0 0 0" xyz="0 0 0"/>
    <geometry>
      <mesh filename="package://fusion2urdf/bin_stl/base_link_m-binary.stl"/>
    </geometry>
  </collision>
</link>
<link name="middle_wheel_right">
  <inertial>
    <origin rpy="0 0 0" xyz="0.135999 0.040876 0.093783"/>
    <mass value="0.130978"/>
    <inertia ixx="0.001602" ixy="-0.000876" ixz="-0.000502" iyy="0.004794" iyz="-0.00201" izz="0.003861"/>
  </inertial>
  <visual>
    <origin rpy="0 0 0" xyz="0.135999 0.040876 0.093783"/>
    <geometry>
      <mesh filename="package://fusion2urdf/bin_stl/middle_wheel_right_m-binary.stl"/>
    </geometry>
    <material name="silver">
      <color rgba="1 0 0 1"/>
    </material>
  </visual>
  <collision>
    <origin rpy="0 0 0" xyz="0.135999 0.040876 0.093783"/>
    <geometry>
      <mesh filename="package://fusion2urdf/bin_stl/middle_wheel_right_m-binary.stl"/>
    </geometry>
  </collision>
</link>
<link name="middle_wheel_left">
  <inertial>
    <origin rpy="0 0 0" xyz="-0.135999 0.040876 0.093783"/>
    <mass value="0.130978"/>
    <inertia ixx="0.001602" ixy="0.000876" ixz="-0.000502" iyy="0.004794" iyz="0.00201" izz="0.003861"/>
  </inertial>
  <visual>
    <origin rpy="0 0 0" xyz="-0.135999 0.040876 0.093783"/>
    <geometry>
      <mesh filename="package://fusion2urdf/bin_stl/middle_wheel_left_m-binary.stl"/>
    </geometry>
    <material name="silver">
      <color rgba="1 0 0 1"/>
    </material>
  </visual>
  <collision>
    <origin rpy="0 0 0" xyz="-0.135999 0.040876 0.093783"/>
    <geometry>
      <mesh filename="package://fusion2urdf/bin_stl/middle_wheel_left_m-binary.stl"/>
    </geometry>
  </collision>
</link>
<link name="back_leg_right">
  <inertial>
    <origin rpy="0 0 0" xyz="0.068 -0.0344 -0.0338"/>
    <mass value="0.198625"/>
    <inertia ixx="0.002152" ixy="0.000363" ixz="0.000189" iyy="0.002518" iyz="-0.000188" izz="0.003789"/>
  </inertial>
  <visual>
    <origin rpy="0 0 0" xyz="0.068 -0.0344 -0.0338"/>
    <geometry>
      <mesh filename="package://fusion2urdf/bin_stl/back_leg_right_m-binary.stl"/>
    </geometry>
    <material name="silver">
      <color rgba="1 0 0 1"/>
    </material>
  </visual>
  <collision>
    <origin rpy="0 0 0" xyz="0.068 -0.0344 -0.0338"/>
    <geometry>
      <mesh filename="package://fusion2urdf/bin_stl/back_leg_right_m-binary.stl"/>
    </geometry>
  </collision>
</link>
<link name="front_wheel_left">
  <inertial>
    <origin rpy="0 0 0" xyz="-0.136399 0.212358 0.095775"/>
    <mass value="0.130978"/>
    <inertia ixx="0.007339" ixy="0.004424" ixz="-0.002664" iyy="0.004649" iyz="0.001995" izz="0.009354"/>
  </inertial>
  <visual>
    <origin rpy="0 0 0" xyz="-0.136399 0.212358 0.095775"/>
    <geometry>
      <mesh filename="package://fusion2urdf/bin_stl/front_wheel_left_m-binary.stl"/>
    </geometry>
    <material name="silver">
      <color rgba="1 0 0 1"/>
    </material>
  </visual>
  <collision>
    <origin rpy="0 0 0" xyz="-0.136399 0.212358 0.095775"/>
    <geometry>
      <mesh filename="package://fusion2urdf/bin_stl/front_wheel_left_m-binary.stl"/>
    </geometry>
  </collision>
</link>
<link name="back_wheel_left">
  <inertial>
    <origin rpy="0 0 0" xyz="-0.126994 -0.130414 0.085529"/>
    <mass value="0.130978"/>
    <inertia ixx="0.003417" ixy="-0.002625" ixz="0.001461" iyy="0.004184" iyz="0.001721" izz="0.005454"/>
  </inertial>
  <visual>
    <origin rpy="0 0 0" xyz="-0.126994 -0.130414 0.085529"/>
    <geometry>
      <mesh filename="package://fusion2urdf/bin_stl/back_wheel_left_m-binary.stl"/>
    </geometry>
    <material name="silver">
      <color rgba="1 0 0 1"/>
    </material>
  </visual>
  <collision>
    <origin rpy="0 0 0" xyz="-0.126994 -0.130414 0.085529"/>
    <geometry>
      <mesh filename="package://fusion2urdf/bin_stl/back_wheel_left_m-binary.stl"/>
    </geometry>
  </collision>
</link>
<link name="front_leg_right">
  <inertial>
    <origin rpy="0 0 0" xyz="0.099999 0.127661 0.022845"/>
    <mass value="0.154601"/>
    <inertia ixx="0.003903" ixy="-0.00241" ixz="-0.001207" iyy="0.003117" iyz="-0.001163" izz="0.005454"/>
  </inertial>
  <visual>
    <origin rpy="0 0 0" xyz="0.099999 0.127661 0.022845"/>
    <geometry>
      <mesh filename="package://fusion2urdf/bin_stl/front_leg_right_m-binary.stl"/>
    </geometry>
    <material name="silver">
      <color rgba="1 0 0 1"/>
    </material>
  </visual>
  <collision>
    <origin rpy="0 0 0" xyz="0.099999 0.127661 0.022845"/>
    <geometry>
      <mesh filename="package://fusion2urdf/bin_stl/front_leg_right_m-binary.stl"/>
    </geometry>
  </collision>
</link>
<link name="front_leg_left">
  <inertial>
    <origin rpy="0 0 0" xyz="-0.099999 0.127661 0.022845"/>
    <mass value="0.154601"/>
    <inertia ixx="0.003903" ixy="0.002405" ixz="-0.001207" iyy="0.003111" iyz="0.001161" izz="0.005448"/>
  </inertial>
  <visual>
    <origin rpy="0 0 0" xyz="-0.099999 0.127661 0.022845"/>
    <geometry>
      <mesh filename="package://fusion2urdf/bin_stl/front_leg_left_m-binary.stl"/>
    </geometry>
    <material name="silver">
      <color rgba="1 0 0 1"/>
    </material>
  </visual>
  <collision>
    <origin rpy="0 0 0" xyz="-0.099999 0.127661 0.022845"/>
    <geometry>
      <mesh filename="package://fusion2urdf/bin_stl/front_leg_left_m-binary.stl"/>
    </geometry>
  </collision>
</link>
<link name="front_wheel_right">
  <inertial>
    <origin rpy="0 0 0" xyz="0.136999 0.212358 0.095775"/>
    <mass value="0.130978"/>
    <inertia ixx="0.007339" ixy="-0.004441" ixz="-0.002664" iyy="0.004674" iyz="-0.002003" izz="0.009379"/>
  </inertial>
  <visual>
    <origin rpy="0 0 0" xyz="0.136999 0.212358 0.095775"/>
    <geometry>
      <mesh filename="package://fusion2urdf/bin_stl/front_wheel_right_m-binary.stl"/>
    </geometry>
    <material name="silver">
      <color rgba="1 0 0 1"/>
    </material>
  </visual>
  <collision>
    <origin rpy="0 0 0" xyz="0.136999 0.212358 0.095775"/>
    <geometry>
      <mesh filename="package://fusion2urdf/bin_stl/front_wheel_right_m-binary.stl"/>
    </geometry>
  </collision>
</link>
<link name="back_leg_left ">
  <inertial>
    <origin rpy="0 0 0" xyz="-0.068 -0.0344 -0.0338"/>
    <mass value="0.198625"/>
    <inertia ixx="0.002152" ixy="-0.000337" ixz="0.000189" iyy="0.00247" iyz="0.00017" izz="0.003741"/>
  </inertial>
  <visual>
    <origin rpy="0 0 0" xyz="-0.068 -0.0344 -0.0338"/>
    <geometry>
      <mesh filename="package://fusion2urdf/bin_stl/back_leg_left _m-binary.stl"/>
    </geometry>
    <material name="silver">
      <color rgba="1 0 0 1"/>
    </material>
  </visual>
  <collision>
    <origin rpy="0 0 0" xyz="-0.068 -0.0344 -0.0338"/>
    <geometry>
      <mesh filename="package://fusion2urdf/bin_stl/back_leg_left _m-binary.stl"/>
    </geometry>
  </collision>
</link>
<link name="back_wheel_right">
  <inertial>
    <origin rpy="0 0 0" xyz="0.131994 -0.130414 0.085529"/>
    <mass value="0.130978"/>
    <inertia ixx="0.003417" ixy="0.00271" ixz="0.001461" iyy="0.004389" iyz="-0.001777" izz="0.005658"/>
  </inertial>
  <visual>
    <origin rpy="0 0 0" xyz="0.131994 -0.130414 0.085529"/>
    <geometry>
      <mesh filename="package://fusion2urdf/bin_stl/back_wheel_right_m-binary.stl"/>
    </geometry>
    <material name="silver">
      <color rgba="1 0 0 1"/>
    </material>
  </visual>
  <collision>
    <origin rpy="0 0 0" xyz="0.131994 -0.130414 0.085529"/>
    <geometry>
      <mesh filename="package://fusion2urdf/bin_stl/back_wheel_right_m-binary.stl"/>
    </geometry>
  </collision>
</link>
<joint name="wheel_middle_right" type="continuous">
  <origin rpy="0 0 0" xyz="-0.036 0.086785 -0.070938"/>
  <parent link="front_leg_right"/>
  <child link="middle_wheel_right"/>
  <axis xyz="0.01 0.0 -0.0"/>
</joint>
<joint name="wheel_middle_left" type="continuous">
  <origin rpy="0 0 0" xyz="0.036 0.086785 -0.070938"/>
  <parent link="front_leg_left"/>
  <child link="middle_wheel_left"/>
  <axis xyz="0.01 -0.0 0.0"/>
</joint>
<joint name="leg_back_right" type="continuous">
  <origin rpy="0 0 0" xyz="-0.068 0.0344 0.0338"/>
  <parent link="base_link"/>
  <child link="back_leg_right"/>
  <axis xyz="-0.01 -0.0 -0.0"/>
</joint>
<joint name="wheel_front_left" type="continuous">
  <origin rpy="0 0 0" xyz="0.0364 -0.084697 -0.07293"/>
  <parent link="front_leg_left"/>
  <child link="front_wheel_left"/>
  <axis xyz="0.01 0.0 0.0"/>
</joint>
<joint name="wheel_back_left" type="continuous">
  <origin rpy="0 0 0" xyz="0.058994 0.096014 -0.119329"/>
  <parent link="back_leg_left "/>
  <child link="back_wheel_left"/>
  <axis xyz="0.01 -0.0 0.0"/>
</joint>
<joint name="leg_front_right" type="continuous">
  <origin rpy="0 0 0" xyz="-0.031999 -0.162061 -0.056645"/>
  <parent link="back_leg_right"/>
  <child link="front_leg_right"/>
  <axis xyz="0.01 0.0 0.0"/>
</joint>
<joint name="leg_front_left" type="continuous">
  <origin rpy="0 0 0" xyz="0.031999 -0.162061 -0.056645"/>
  <parent link="back_leg_left "/>
  <child link="front_leg_left"/>
  <axis xyz="0.01 0.0 0.0"/>
</joint>
<joint name="wheel_front_right" type="continuous">
  <origin rpy="0 0 0" xyz="-0.037 -0.084697 -0.07293"/>
  <parent link="front_leg_right"/>
  <child link="front_wheel_right"/>
  <axis xyz="0.01 -0.0 -0.0"/>
</joint>
<joint name="leg_back_left" type="continuous">
  <origin rpy="0 0 0" xyz="0.068 0.0344 0.0338"/>
  <parent link="base_link"/>
  <child link="back_leg_left "/>
  <axis xyz="-0.01 -0.0 -0.0"/>
</joint>
<joint name="wheel_back_right" type="continuous">
  <origin rpy="0 0 0" xyz="-0.063994 0.096014 -0.119329"/>
  <parent link="back_leg_right"/>
  <child link="back_wheel_right"/>
  <axis xyz="0.01 0.0 -0.0"/>
</joint>
</robot>